Workbook

Sheet Guida
A1: CONTROLLO DI GESTIONE CON L'INTELLIGENZA ARTIFICIALE
A2: File Excel che accompagna il libro · Autrice: Tania Cilio
A3: © 2026 Tania Cilio. Tutti i diritti riservati.
A4: Il file segue il libro capitolo per capitolo, con le formule scritte nelle celle: si vede come nasce ogni numero e lo si può rifare con i propri dati.
A5: Il foglio «Impresa_guida» contiene i dati di partenza del caso del libro. I fogli «Cap_01» … «Cap_20» li usano nei calcoli di ogni capitolo.
A6: Celle blu su fondo giallo: dati da cambiare. Celle nere: formule. Colonna «Valore atteso (libro)»: il numero stampato nel libro o il risultato atteso di un controllo (per esempio una differenza uguale a zero). Colonna «Controllo»: OK se il calcolo lo ritrova.
A7: Se si cambiano i dati, i controlli possono diventare «DIVERSO»: è normale, perché i numeri non sono più quelli del libro.
A8: Il foglio «Controlli» riunisce tutti i confronti con il libro. Il foglio «Bilancio_Alfa_2024» è la base delle richieste 16-22 e 30 del file Word con le trenta richieste.
A10: Foglio | B10: Contenuto | C10: Capitoli del libro
A11: Impresa_guida | B11: Dati di partenza del caso del libro (paragrafo 19.3) | C11: tutti
A12: Parte I - Fondamenti di contabilità e analisi economica
A13: Cap_01 | B13: Capitolo 1 - Leggere la realtà economica dell'impresa | C13: 1
A14: Cap_02 | B14: Capitolo 2 - Contabilità generale e contabilità analitica | C14: 2
A15: Cap_03 | B15: Capitolo 3 - Il concetto di costo e le classificazioni | C15: 3
A16: Cap_04 | B16: Capitolo 4 - Comportamento dei costi | C16: 4
A17: Parte II - Contabilità analitica, costing, ABC e ABM
A18: Cap_05 | B18: Capitolo 5 - Oggetti di costo e centri di costo | C18: 5
A19: Cap_06 | B19: Capitolo 6 - Costi diretti, indiretti e allocazione | C19: 6
A20: Cap_07 | B20: Capitolo 7 - Full Costing | C20: 7
A21: Cap_08 | B21: Capitolo 8 - Direct Costing e margine di contribuzione | C21: 8
A22: Cap_09 | B22: Capitolo 9 - Break-even e analisi costo-volume-risultato | C22: 9
A23: Cap_10 | B23: Capitolo 10 - Activity Based Costing | C23: 10
A24: Cap_11 | B24: Capitolo 11 - Activity Based Management | C24: 11
A25: Parte III - Programmazione, budget e analisi degli scostamenti
A26: Cap_12 | B26: Capitolo 12 - Budget | C26: 12
A27: Cap_13 | B27: Capitolo 13 - Budget operativo | C27: 13
A28: Cap_14 | B28: Capitolo 14 - Budget, consuntivo e analisi degli scostamenti | C28: 14
A29: Parte IV - Decisioni economiche
A30: Cap_15 | B30: Capitolo 15 - Costi rilevanti e decisioni | C30: 15
A31: Cap_16 | B31: Capitolo 16 - Make or Buy | C31: 16
A32: Cap_17 | B32: Capitolo 17 - Pricing | C32: 17
A33: Cap_18 | B33: Capitolo 18 - Ottimizzazione dei margini e alternative produttive | C33: 18
A34: Parte V - Intelligenza artificiale e misurazione delle prestazioni
A35: Cap_19 | B35: Capitolo 19 - L'intelligenza artificiale nel controllo di gestione | C35: 19
A36: Cap_20 | B36: Capitolo 20 - KPI essenziali per il controllo di gestione | C36: 20
A37: Esercizi, formule, glossario e controlli
A38: Esercizi_Costi | B38: Classificare i costi (18 voci) | C38: 3, 4, 8, 15, 16
A39: Esercizi_Analitica | B39: Allocazione, centri e basi | C39: 5, 6, 10, 11
A40: Esercizi_Costing | B40: Full Costing, Direct Costing, pareggio, ABC | C40: 7, 8, 9, 10
A41: Esercizi_Pianificazione | B41: Budget e scostamenti | C41: 13, 14
...

Sheet Impresa_guida
A1: Impresa guida - dataset master (paragrafo 19.3)
A2: Controllo di gestione con l'intelligenza artificiale - file Excel che accompagna il libro
A3: Celle blu su fondo giallo: dati da cambiare. Celle nere: formule. «Valore atteso (libro)» e «Controllo» confrontano il calcolo con il numero stampato nel libro.
A4: I dati di partenza di tutto il libro. Le celle blu su fondo giallo sono dati: cambiandole si ricalcolano tutti i fogli dei capitoli.
A6: Linee di prodotto
A7: Voce | B7: Valore | C7: Unità | D7: Valore atteso (libro) | E7: Controllo | F7: Fonte nel libro
A8: Linea A - unità vendute | B8: 8000 | C8: unità | F8: paragrafo 19.3
A9: Linea A - prezzo netto unitario | B9: 180 | C9: euro/unità | F9: paragrafo 19.3
A10: Linea A - costo variabile unitario | B10: 117 | C10: euro/unità | F10: paragrafo 19.3
A11: Linea A - ore macchina per unità | B11: 1.5 | C11: ore/unità | F11: paragrafo 19.3
A12: Linea B - unità vendute | B12: 12000 | C12: unità | F12: paragrafo 19.3
A13: Linea B - prezzo netto unitario | B13: 114 | C13: euro/unità | F13: paragrafo 19.3
A14: Linea B - costo variabile unitario | B14: 76 | C14: euro/unità | F14: paragrafo 19.3
A15: Linea B - ore macchina per unità | B15: 0.5 | C15: ore/unità | F15: paragrafo 19.3
A16: Linea C - unità vendute | B16: 2000 | C16: unità | F16: paragrafo 19.3
A17: Linea C - prezzo netto unitario | B17: 289 | C17: euro/unità | F17: paragrafo 19.3
A18: Linea C - costo variabile unitario | B18: 238 | C18: euro/unità | F18: paragrafo 19.3
A19: Linea C - ore macchina per unità | B19: 3 | C19: ore/unità | F19: paragrafo 19.3
A21: Struttura e capacità
A22: Voce | B22: Valore | C22: Unità | D22: Valore atteso (libro) | E22: Controllo | F22: Fonte nel libro
A23: Struttura base - attività commerciali e logistiche | B23: 570000 | C23: euro | F23: paragrafo 19.3
A24: Struttura base - costi indiretti di produzione | B24: 120000 | C24: euro | F24: paragrafo 19.3
A25: Struttura base - costi amministrativi | B25: 46000 | C25: euro | F25: paragrafo 19.3
A26: Capacità ordinaria del reparto | B26: 21000 | C26: ore | F26: paragrafo 19.3
A27: Costo di un'ora di capacità esterna | B27: 28 | C27: euro/ora | F27: paragrafo 19.3
A29: Risultati (calcolati)
A30: Voce | B30: Valore | C30: Unità | D30: Valore atteso (libro) | E30: Controllo | F30: Fonte nel libro
A31: Ricavi linea A | B31: =$B$8*$B$9 -> 1440000 | C31: euro | D31: 1440000 | E31: =IF(ABS(B31-D31)<=0.5,"OK","DIVERSO") -> OK | F31: capitolo 1; paragrafo 19.3
A32: Ricavi linea B | B32: =$B$12*$B$13 -> 1368000 | C32: euro | D32: 1368000 | E32: =IF(ABS(B32-D32)<=0.5,"OK","DIVERSO") -> OK | F32: capitolo 1; paragrafo 19.3
A33: Ricavi linea C | B33: =$B$16*$B$17 -> 578000 | C33: euro | D33: 578000 | E33: =IF(ABS(B33-D33)<=0.5,"OK","DIVERSO") -> OK | F33: capitolo 1; paragrafo 19.3
A34: Ricavi totali | B34: =$B$31+$B$32+$B$33 -> 3386000 | C34: euro | D34: 3386000 | E34: =IF(ABS(B34-D34)<=0.5,"OK","DIVERSO") -> OK | F34: capitolo 1; paragrafo 19.3
A35: Costi variabili totali | B35: =$B$8*$B$10+$B$12*$B$14+$B$16*$B$18 -> 2324000 | C35: euro | D35: 2324000 | E35: =IF(ABS(B35-D35)<=0.5,"OK","DIVERSO") -> OK | F35: capitolo 1; paragrafo 19.3
A36: Margine di contribuzione totale | B36: =$B$34-$B$35 -> 1062000 | C36: euro | D36: 1062000 | E36: =IF(ABS(B36-D36)<=0.5,"OK","DIVERSO") -> OK | F36: capitolo 1; paragrafo 19.3
A37: Ore macchina richieste | B37: =$B$8*$B$11+$B$12*$B$15+$B$16*$B$19 -> 24000 | C37: ore | D37: 24000 | E37: =IF(ABS(B37-D37)<=0.5,"OK","DIVERSO") -> OK | F37: capitolo 1; paragrafo 19.3
A38: Ore di capacità esterna | B38: =MAX($B$37-$B$26,0) -> 3000 | C38: ore | D38: 3000 | E38: =IF(ABS(B38-D38)<=0.5,"OK","DIVERSO") -> OK | F38: capitolo 1; paragrafo 19.3
A39: Costo della capacità esterna | B39: =$B$38*$B$27 -> 84000 | C39: euro | D39: 84000 | E39: =IF(ABS(B39-D39)<=0.5,"OK","DIVERSO") -> OK | F39: capitolo 1; paragrafo 19.3
A40: Struttura base | B40: =$B$23+$B$24+$B$25 -> 736000 | C40: euro | D40: 736000 | E40: =IF(ABS(B40-D40)<=0.5,"OK","DIVERSO") -> OK | F40: capitolo 1; paragrafo 19.3
A41: Costi della struttura | B41: =$B$40+$B$39 -> 820000 | C41: euro | D41: 820000 | E41: =IF(ABS(B41-D41)<=0.5,"OK","DIVERSO") -> OK | F41: capitolo 1; paragrafo 19.3
A42: Risultato operativo | B42: =$B$36-$B$41 -> 242000 | C42: euro | D42: 242000 | E42: =IF(ABS(B42-D42)<=0.5,"OK","DIVERSO") -> OK | F42: capitolo 1; paragrafo 19.3

Sheet Cap_01
A1: Capitolo 1 - Leggere la realtà economica dell'impresa
A2: Controllo di gestione con l'intelligenza artificiale - file Excel che accompagna il libro
A3: Celle blu su fondo giallo: dati da cambiare. Celle nere: formule. «Valore atteso (libro)» e «Controllo» confrontano il calcolo con il numero stampato nel libro.
A4: Il Conto Economico letto per gradini e la differenza fra costo, acquisto, pagamento, ricavo e incasso.
A6: Conto Economico per gradini - esempio
A7: Il risultato si forma per gradini: margine di contribuzione, risultato operativo, risultato economico; capitolo 1
A8: Voce | B8: Valore | C8: Unità | D8: Valore atteso (libro) | E8: Controllo | F8: Fonte nel libro
A9: Ricavi di vendita | B9: 200000 | C9: euro | F9: capitolo 1
A10: Costi variabili | B10: 120000 | C10: euro | F10: capitolo 1
A11: Margine di contribuzione | B11: =$B$9-$B$10 -> 80000 | C11: euro | D11: 80000 | E11: =IF(ABS(B11-D11)<=0.5,"OK","DIVERSO") -> OK | F11: capitolo 1
A12: Costi fissi di struttura | B12: 55000 | C12: euro | F12: capitolo 1
A13: Risultato operativo | B13: =$B$11-$B$12 -> 25000 | C13: euro | D13: 25000 | E13: =IF(ABS(B13-D13)<=0.5,"OK","DIVERSO") -> OK | F13: capitolo 1
A14: Oneri finanziari | B14: 5000 | C14: euro | F14: capitolo 1
A15: Risultato economico del periodo | B15: =$B$13-$B$14 -> 20000 | C15: euro | D15: 20000 | E15: =IF(ABS(B15-D15)<=0.5,"OK","DIVERSO") -> OK | F15: capitolo 1
A17: Acquisto, costo e magazzino
A18: Il costo è la risorsa consumata, non l'acquisto: la parte non consumata resta in magazzino; capitolo 1
A19: Voce | B19: Valore | C19: Unità | D19: Valore atteso (libro) | E19: Controllo | F19: Fonte nel libro
A20: Acquisto di materia prima | B20: 30000 | C20: euro | F20: capitolo 1
A21: Materia consumata nel periodo | B21: 20000 | C21: euro | F21: capitolo 1
A22: Costo del periodo | B22: =$B$21 -> 20000 | C22: euro | D22: 20000 | E22: =IF(ABS(B22-D22)<=0.5,"OK","DIVERSO") -> OK | F22: capitolo 1
A23: Rimane in magazzino (attività) | B23: =$B$20-$B$21 -> 10000 | C23: euro | D23: 10000 | E23: =IF(ABS(B23-D23)<=0.5,"OK","DIVERSO") -> OK | F23: capitolo 1
A25: Ammortamento: costo senza pagamento
A26: Un macchinario pagato una volta diventa costo anno per anno; capitolo 1
A27: Voce | B27: Valore | C27: Unità | D27: Valore atteso (libro) | E27: Controllo | F27: Fonte nel libro
A28: Costo del macchinario | B28: 100000 | C28: euro | F28: capitolo 1
A29: Anni di utilizzo | B29: 10 | C29: anni | F29: capitolo 1
A30: Ammortamento annuo | B30: =$B$28/$B$29 -> 10000 | C30: euro | D30: 10000 | E30: =IF(ABS(B30-D30)<=0.5,"OK","DIVERSO") -> OK | F30: capitolo 1
A32: Impresa guida - Conto Economico per gradini
A33: Il Conto Economico dell'esercizio letto per gradini, dai dati del foglio Impresa_guida; capitolo 1
A34: Voce | B34: Valore | C34: Unità | D34: Valore atteso (libro) | E34: Controllo | F34: Fonte nel libro
A35: Ricavi di vendita | B35: =Impresa_guida!$B$34 -> 3386000 | C35: euro | D35: 3386000 | E35: =IF(ABS(B35-D35)<=0.5,"OK","DIVERSO") -> OK | F35: capitolo 1
A36: Costi variabili | B36: =Impresa_guida!$B$35 -> 2324000 | C36: euro | D36: 2324000 | E36: =IF(ABS(B36-D36)<=0.5,"OK","DIVERSO") -> OK | F36: capitolo 1
A37: Margine di contribuzione | B37: =$B$35-$B$36 -> 1062000 | C37: euro | D37: 1062000 | E37: =IF(ABS(B37-D37)<=0.5,"OK","DIVERSO") -> OK | F37: capitolo 1
A38: Costi della struttura | B38: =Impresa_guida!$B$41 -> 820000 | C38: euro | D38: 820000 | E38: =IF(ABS(B38-D38)<=0.5,"OK","DIVERSO") -> OK | F38: capitolo 1
A39: Risultato operativo | B39: =$B$37-$B$38 -> 242000 | C39: euro | D39: 242000 | E39: =IF(ABS(B39-D39)<=0.5,"OK","DIVERSO") -> OK | F39: capitolo 1
A41: Impresa guida - lettura finanziaria
A42: Ricavi e incassi non coincidono: con i crediti in aumento l'incasso è minore del ricavo; l'ammortamento è costo senza pagamento; capitolo 1
A43: Voce | B43: Valore | C43: Unità | D43: Valore atteso (libro) | E43: Controllo | F43: Fonte nel libro
A44: Ammortamento impianti (costo senza pagamento) | B44: 74000 | C44: euro | F44: capitolo 1
A45: Aumento dei crediti verso clienti (ipotesi del caso) | B45: 180000 | C45: euro | F45: capitolo 1
...

Sheet Cap_02
A1: Capitolo 2 - Contabilità generale e contabilità analitica
A2: Controllo di gestione con l'intelligenza artificiale - file Excel che accompagna il libro
A3: Celle blu su fondo giallo: dati da cambiare. Celle nere: formule. «Valore atteso (libro)» e «Controllo» confrontano il calcolo con il numero stampato nel libro.
A4: Il partitario della struttura dell'impresa guida letto per natura e per destinazione, con le quadrature.
A6: Partitario della struttura - reparto di lavorazione
A7: Destinazione reparto: le voci per natura; capitolo 2
A8: Voce | B8: Valore | C8: Unità | D8: Valore atteso (libro) | E8: Controllo | F8: Fonte nel libro
A9: Retribuzioni | B9: 46000 | C9: euro | F9: capitolo 2
A10: Ammortamenti | B10: =Cap_01!$B$44 -> 74000 | C10: euro | F10: capitolo 2
A11: Lavorazioni esterne e straordinari | B11: =Impresa_guida!$B$39 -> 84000 | C11: euro | D11: 84000 | E11: =IF(ABS(B11-D11)<=0.5,"OK","DIVERSO") -> OK | F11: capitolo 2
A12: Servizi, sistemi e materiali | B12: 0 | C12: euro | F12: capitolo 2
A13: Totale reparto | B13: =$B$9+$B$10+$B$11+$B$12 -> 204000 | C13: euro | D13: 204000 | E13: =IF(ABS(B13-D13)<=0.5,"OK","DIVERSO") -> OK | F13: capitolo 2
A15: Partitario della struttura - funzioni che servono i clienti
A16: Gestione ordini, consegne, assistenza tecnica; capitolo 2
A17: Voce | B17: Valore | C17: Unità | D17: Valore atteso (libro) | E17: Controllo | F17: Fonte nel libro
A18: Gestione ordini - retribuzioni | B18: 186000 | C18: euro | F18: capitolo 2
A19: Gestione ordini - servizi, sistemi e materiali | B19: 54000 | C19: euro | F19: capitolo 2
A20: Totale gestione ordini | B20: =$B$18+$B$19 -> 240000 | C20: euro | D20: 240000 | E20: =IF(ABS(B20-D20)<=0.5,"OK","DIVERSO") -> OK | F20: capitolo 2
A21: Consegne - retribuzioni | B21: 42000 | C21: euro | F21: capitolo 2
A22: Consegne - servizi (trasporti su vendite) | B22: 138000 | C22: euro | F22: capitolo 2
A23: Totale consegne | B23: =$B$21+$B$22 -> 180000 | C23: euro | D23: 180000 | E23: =IF(ABS(B23-D23)<=0.5,"OK","DIVERSO") -> OK | F23: capitolo 2
A24: Assistenza tecnica - retribuzioni | B24: 118000 | C24: euro | F24: capitolo 2
A25: Assistenza tecnica - ricambi e trasferte | B25: 32000 | C25: euro | F25: capitolo 2
A26: Totale assistenza tecnica | B26: =$B$24+$B$25 -> 150000 | C26: euro | D26: 150000 | E26: =IF(ABS(B26-D26)<=0.5,"OK","DIVERSO") -> OK | F26: capitolo 2
A27: Funzioni che servono i clienti | B27: =$B$20+$B$23+$B$26 -> 570000 | C27: euro | D27: 570000 | E27: =IF(ABS(B27-D27)<=0.5,"OK","DIVERSO") -> OK | F27: capitolo 2
A29: Partitario della struttura - amministrazione
A30: Destinazione amministrazione; capitolo 2
A31: Voce | B31: Valore | C31: Unità | D31: Valore atteso (libro) | E31: Controllo | F31: Fonte nel libro
A32: Retribuzioni amministrative | B32: =Impresa_guida!$B$25 -> 46000 | C32: euro | D32: 46000 | E32: =IF(ABS(B32-D32)<=0.5,"OK","DIVERSO") -> OK | F32: capitolo 2
A33: Totale amministrazione | B33: =$B$32 -> 46000 | C33: euro | D33: 46000 | E33: =IF(ABS(B33-D33)<=0.5,"OK","DIVERSO") -> OK | F33: capitolo 2
A35: Totali per natura
A36: La lettura della contabilità generale; capitolo 2
A37: Voce | B37: Valore | C37: Unità | D37: Valore atteso (libro) | E37: Controllo | F37: Fonte nel libro
A38: Retribuzioni | B38: =$B$9+$B$18+$B$21+$B$24+$B$32 -> 438000 | C38: euro | D38: 438000 | E38: =IF(ABS(B38-D38)<=0.5,"OK","DIVERSO") -> OK | F38: capitolo 2
A39: Ammortamenti | B39: =$B$10 -> 74000 | C39: euro | D39: 74000 | E39: =IF(ABS(B39-D39)<=0.5,"OK","DIVERSO") -> OK | F39: capitolo 2
A40: Lavorazioni esterne e straordinari | B40: =$B$11 -> 84000 | C40: euro | D40: 84000 | E40: =IF(ABS(B40-D40)<=0.5,"OK","DIVERSO") -> OK | F40: capitolo 2
A41: Servizi, sistemi e materiali | B41: =$B$12+$B$19+$B$22+$B$25 -> 224000 | C41: euro | D41: 224000 | E41: =IF(ABS(B41-D41)<=0.5,"OK","DIVERSO") -> OK | F41: capitolo 2
A42: Totale per natura | B42: =$B$38+$B$39+$B$40+$B$41 -> 820000 | C42: euro | D42: 820000 | E42: =IF(ABS(B42-D42)<=0.5,"OK","DIVERSO") -> OK | F42: capitolo 2
A44: Quadratura natura - destinazione
A45: La riclassificazione sposta gli importi, non li crea e non li perde; capitolo 2
...

Sheet Cap_03
A1: Capitolo 3 - Il concetto di costo e le classificazioni
A2: Controllo di gestione con l'intelligenza artificiale - file Excel che accompagna il libro
A3: Celle blu su fondo giallo: dati da cambiare. Celle nere: formule. «Valore atteso (libro)» e «Controllo» confrontano il calcolo con il numero stampato nel libro.
A4: Il costo come risorsa consumata e la stessa voce letta da più prospettive.
A6: Costo della risorsa consumata
A7: Costo = quantità consumata x valore unitario; il non consumato resta in magazzino; capitolo 3
A8: Voce | B8: Valore | C8: Unità | D8: Valore atteso (libro) | E8: Controllo | F8: Fonte nel libro
A9: Materiale acquistato | B9: 1000 | C9: unità | F9: capitolo 3
A10: Materiale consumato nel mese | B10: 600 | C10: unità | F10: capitolo 3
A11: Valore al chilogrammo | B11: 8 | C11: euro/kg | F11: capitolo 3
A12: Costo del materiale consumato | B12: =$B$10*$B$11 -> 4800 | C12: euro | D12: 4800 | E12: =IF(ABS(B12-D12)<=0.5,"OK","DIVERSO") -> OK | F12: capitolo 3
A13: Valore rimasto in magazzino | B13: =($B$9-$B$10)*$B$11 -> 3200 | C13: euro | D13: 3200 | E13: =IF(ABS(B13-D13)<=0.5,"OK","DIVERSO") -> OK | F13: capitolo 3
A15: Lettura per natura del personale
A16: Il dato per natura segnala l'aumento ma non dice dove nasce; capitolo 3
A17: Voce | B17: Valore | C17: Unità | D17: Valore atteso (libro) | E17: Controllo | F17: Fonte nel libro
A18: Costo del personale - prima | B18: 500000 | C18: euro | F18: capitolo 3
A19: Costo del personale - dopo | B19: 600000 | C19: euro | F19: capitolo 3
A20: Aumento | B20: =$B$19-$B$18 -> 100000 | C20: euro | D20: 100000 | E20: =IF(ABS(B20-D20)<=0.5,"OK","DIVERSO") -> OK | F20: capitolo 3
A22: Costo variabile e costo fisso
A23: Il variabile segue i volumi; il fisso resta nel totale ma scende per unità; capitolo 3
A24: Voce | B24: Valore | C24: Unità | D24: Valore atteso (libro) | E24: Controllo | F24: Fonte nel libro
A25: Materiale per unità | B25: 4 | C25: euro/unità | F25: capitolo 3
A26: Volume 1 | B26: 1000 | C26: unità | F26: capitolo 3
A27: Volume 2 | B27: 1500 | C27: unità | F27: capitolo 3
A28: Costo variabile - volume 1 | B28: =$B$25*$B$26 -> 4000 | C28: euro | D28: 4000 | E28: =IF(ABS(B28-D28)<=0.5,"OK","DIVERSO") -> OK | F28: capitolo 3
A29: Costo variabile - volume 2 | B29: =$B$25*$B$27 -> 6000 | C29: euro | D29: 6000 | E29: =IF(ABS(B29-D29)<=0.5,"OK","DIVERSO") -> OK | F29: capitolo 3
A30: Canone mensile | B30: 10000 | C30: euro | F30: capitolo 3
A31: Costo fisso per unità - volume 1 | B31: =$B$30/$B$26 -> 10 | C31: euro/unità | D31: 10 | E31: =IF(ABS(B31-D31)<=0.005,"OK","DIVERSO") -> OK | F31: capitolo 3
A32: Costo fisso per unità - volume 2 | B32: =$B$30/$B$27 -> 6.6666667 | C32: euro/unità | D32: 6.67 | E32: =IF(ABS(B32-D32)<=0.005,"OK","DIVERSO") -> OK | F32: capitolo 3
A34: Impresa guida - la voce lavorazioni esterne
A35: Il comportamento dipende dalle ore oltre le 21.000: 84.000 / 28 = 3.000 ore; capitolo 3
A36: Voce | B36: Valore | C36: Unità | D36: Valore atteso (libro) | E36: Controllo | F36: Fonte nel libro
A37: Ore coperte dalla voce (84.000 / 28) | B37: =Cap_02!$B$11/Impresa_guida!$B$27 -> 3000 | C37: ore | D37: 3000 | E37: =IF(ABS(B37-D37)<=0.5,"OK","DIVERSO") -> OK | F37: capitolo 3
A38: Ore richieste oltre la capacità | B38: =Impresa_guida!$B$37-Impresa_guida!$B$26 -> 3000 | C38: ore | D38: 3000 | E38: =IF(ABS(B38-D38)<=0.5,"OK","DIVERSO") -> OK | F38: capitolo 3
A39: Differenza | B39: =$B$37-$B$38 -> 0 | C39: ore | D39: 0 | E39: =IF(ABS(B39-D39)<=0.5,"OK","DIVERSO") -> OK | F39: capitolo 3
A41: Impresa guida - struttura rispetto alla decisione sui volumi
A42: I dieci conti divisi in tre gruppi; capitolo 3
A43: Voce | B43: Valore | C43: Unità | D43: Valore atteso (libro) | E43: Controllo | F43: Fonte nel libro
A44: Riducibili entro l'esercizio (lavorazioni, trasporti, ricambi) | B44: =Cap_02!$B$11+Cap_02!$B$22+Cap_02!$B$25 -> 254000 | C44: euro | D44: 254000 | E44: =IF(ABS(B44-D44)<=0.5,"OK","DIVERSO") -> OK | F44: capitolo 3
A45: Riducibili nelle decisioni di volume del caso | B45: =Cap_02!$B$11 -> 84000 | C45: euro | D45: 84000 | E45: =IF(ABS(B45-D45)<=0.5,"OK","DIVERSO") -> OK | F45: capitolo 3
...

Sheet Cap_04
A1: Capitolo 4 - Comportamento dei costi
A2: Controllo di gestione con l'intelligenza artificiale - file Excel che accompagna il libro
A3: Celle blu su fondo giallo: dati da cambiare. Celle nere: formule. «Valore atteso (libro)» e «Controllo» confrontano il calcolo con il numero stampato nel libro.
A4: Costi variabili, fissi, misti e a gradini, la funzione di costo e la simulazione dei livelli di attività dell'impresa guida.
A6: Costo variabile
A7: Costo variabile totale = costo variabile unitario x quantità; capitolo 4
A8: Voce | B8: Valore | C8: Unità | D8: Valore atteso (libro) | E8: Controllo | F8: Fonte nel libro
A9: Materiale per unità | B9: 6 | C9: euro/unità | F9: capitolo 4
A10: Quantità 1 | B10: 1000 | C10: unità | F10: capitolo 4
A11: Quantità 2 | B11: 1500 | C11: unità | F11: capitolo 4
A12: Quantità 3 | B12: 2000 | C12: unità | F12: capitolo 4
A13: Costo variabile totale - quantità 1 | B13: =$B$9*$B$10 -> 6000 | C13: euro | D13: 6000 | E13: =IF(ABS(B13-D13)<=0.5,"OK","DIVERSO") -> OK | F13: capitolo 4
A14: Costo variabile totale - quantità 2 | B14: =$B$9*$B$11 -> 9000 | C14: euro | D14: 9000 | E14: =IF(ABS(B14-D14)<=0.5,"OK","DIVERSO") -> OK | F14: capitolo 4
A15: Costo variabile totale - quantità 3 | B15: =$B$9*$B$12 -> 12000 | C15: euro | D15: 12000 | E15: =IF(ABS(B15-D15)<=0.5,"OK","DIVERSO") -> OK | F15: capitolo 4
A17: Costo fisso e costo fisso unitario
A18: Costo fisso unitario = costo fisso totale / quantità: scende quando il volume cresce; capitolo 4
A19: Voce | B19: Valore | C19: Unità | D19: Valore atteso (libro) | E19: Controllo | F19: Fonte nel libro
A20: Canone mensile | B20: 12000 | C20: euro | F20: capitolo 4
A21: Costo fisso unitario - quantità 1 | B21: =$B$20/$B$10 -> 12 | C21: euro/unità | D21: 12 | E21: =IF(ABS(B21-D21)<=0.005,"OK","DIVERSO") -> OK | F21: capitolo 4
A22: Costo fisso unitario - quantità 2 | B22: =$B$20/$B$11 -> 8 | C22: euro/unità | D22: 8 | E22: =IF(ABS(B22-D22)<=0.005,"OK","DIVERSO") -> OK | F22: capitolo 4
A23: Costo fisso unitario - quantità 3 | B23: =$B$20/$B$12 -> 6 | C23: euro/unità | D23: 6 | E23: =IF(ABS(B23-D23)<=0.005,"OK","DIVERSO") -> OK | F23: capitolo 4
A25: Capacità inutilizzata - esempio
A26: Le ore non impiegate si espongono a parte, non si caricano sui prodotti; capitolo 4
A27: Voce | B27: Valore | C27: Unità | D27: Valore atteso (libro) | E27: Controllo | F27: Fonte nel libro
A28: Costo della struttura | B28: 120000 | C28: euro | F28: capitolo 4
A29: Ore sostenibili | B29: 12000 | C29: ore | F29: capitolo 4
A30: Ore utilizzate | B30: 9000 | C30: ore | F30: capitolo 4
A31: Costo teorico della capacità per ora | B31: =$B$28/$B$29 -> 10 | C31: euro/ora | D31: 10 | E31: =IF(ABS(B31-D31)<=0.005,"OK","DIVERSO") -> OK | F31: capitolo 4
A32: Capacità disponibile non impiegata | B32: =($B$29-$B$30)*$B$31 -> 30000 | C32: euro | D32: 30000 | E32: =IF(ABS(B32-D32)<=0.5,"OK","DIVERSO") -> OK | F32: capitolo 4
A34: Metodo dei livelli massimo e minimo
A35: Stima della funzione di un costo misto: variabile per ora e componente fissa; capitolo 4
A36: Voce | B36: Valore | C36: Unità | D36: Valore atteso (libro) | E36: Controllo | F36: Fonte nel libro
A37: Livello alto - ore macchina | B37: 8000 | C37: ore | F37: capitolo 4
A38: Livello alto - costo manutenzione | B38: 34000 | C38: euro | F38: capitolo 4
A39: Livello basso - ore macchina | B39: 4000 | C39: ore | F39: capitolo 4
A40: Livello basso - costo manutenzione | B40: 22000 | C40: euro | F40: capitolo 4
A41: Differenza ore | B41: =$B$37-$B$39 -> 4000 | C41: ore | D41: 4000 | E41: =IF(ABS(B41-D41)<=0.5,"OK","DIVERSO") -> OK | F41: capitolo 4
A42: Differenza costo | B42: =$B$38-$B$40 -> 12000 | C42: euro | D42: 12000 | E42: =IF(ABS(B42-D42)<=0.5,"OK","DIVERSO") -> OK | F42: capitolo 4
A43: Costo variabile per ora | B43: =$B$42/$B$41 -> 3 | C43: euro/ora | D43: 3 | E43: =IF(ABS(B43-D43)<=0.005,"OK","DIVERSO") -> OK | F43: capitolo 4
A44: Componente fissa | B44: =$B$38-$B$43*$B$37 -> 10000 | C44: euro | D44: 10000 | E44: =IF(ABS(B44-D44)<=0.5,"OK","DIVERSO") -> OK | F44: capitolo 4
...

Sheet Cap_05
A1: Capitolo 5 - Oggetti di costo e centri di costo
A2: Controllo di gestione con l'intelligenza artificiale - file Excel che accompagna il libro
A3: Celle blu su fondo giallo: dati da cambiare. Celle nere: formule. «Valore atteso (libro)» e «Controllo» confrontano il calcolo con il numero stampato nel libro.
A4: Il piano dei sette centri dell'impresa guida e la sua quadratura con i costi della struttura, prima di qualsiasi allocazione.
A6: Oggetti di costo dell'impresa guida
A7: Linee e canali come oggetti finali: unità, ricavi e clienti per canale; capitolo 5
A8: Voce | B8: Valore | C8: Unità | D8: Valore atteso (libro) | E8: Controllo | F8: Fonte nel libro
A9: Unità vendute, tre linee | B9: =Impresa_guida!$B$8+Impresa_guida!$B$12+Impresa_guida!$B$16 -> 22000 | C9: unità | D9: 22000 | E9: =IF(ABS(B9-D9)<=0.5,"OK","DIVERSO") -> OK | F9: capitolo 5
A10: Ricavi delle tre linee | B10: =Impresa_guida!$B$34 -> 3386000 | C10: euro | D10: 3386000 | E10: =IF(ABS(B10-D10)<=0.5,"OK","DIVERSO") -> OK | F10: capitolo 5
A11: Canale diretto - clienti | B11: 218 | C11: clienti | F11: capitolo 5
A12: Canale diretto - ricavi | B12: 1220000 | C12: euro | F12: capitolo 5
A13: Distributori - ricavi | B13: 2166000 | C13: euro | F13: capitolo 5
A14: Ricavi dei due canali | B14: =$B$12+$B$13 -> 3386000 | C14: euro | D14: 3386000 | E14: =IF(ABS(B14-D14)<=0.5,"OK","DIVERSO") -> OK | F14: capitolo 5
A15: Controllo canali meno linee | B15: =$B$14-Impresa_guida!$B$34 -> 0 | C15: euro | D15: 0 | E15: =IF(ABS(B15-D15)<=0.5,"OK","DIVERSO") -> OK | F15: capitolo 5
A16: Ore macchina richieste dai volumi | B16: =Impresa_guida!$B$37 -> 24000 | C16: ore | D16: 24000 | E16: =IF(ABS(B16-D16)<=0.5,"OK","DIVERSO") -> OK | F16: capitolo 5
A17: Ore di cui il reparto dispone | B17: =Impresa_guida!$B$26 -> 21000 | C17: ore | D17: 21000 | E17: =IF(ABS(B17-D17)<=0.5,"OK","DIVERSO") -> OK | F17: capitolo 5
A19: Piano dei centri - reparto
A20: Tre centri del reparto: due ausiliari e un produttivo, con la misura di attività; capitolo 5
A21: Voce | B21: Valore | C21: Unità | D21: Valore atteso (libro) | E21: Controllo | F21: Fonte nel libro
A22: Manutenzione (ausiliario) | B22: 36000 | C22: euro | F22: capitolo 5
A23: Programmazione e qualità (ausiliario) | B23: 18000 | C23: euro | F23: capitolo 5
A24: Lavorazione (produttivo) | B24: 66000 | C24: euro | F24: capitolo 5
A25: Lavorazione - ore macchina (con le 3.000 esterne) | B25: =Impresa_guida!$B$37 -> 24000 | C25: ore | D25: 24000 | E25: =IF(ABS(B25-D25)<=0.5,"OK","DIVERSO") -> OK | F25: capitolo 5
A26: di cui ore di capacità esterna | B26: =Impresa_guida!$B$38 -> 3000 | C26: ore | D26: 3000 | E26: =IF(ABS(B26-D26)<=0.5,"OK","DIVERSO") -> OK | F26: capitolo 5
A27: Totale centri del reparto | B27: =$B$22+$B$23+$B$24 -> 120000 | C27: euro | D27: 120000 | E27: =IF(ABS(B27-D27)<=0.5,"OK","DIVERSO") -> OK | F27: capitolo 5
A28: Controllo con i costi indiretti di produzione | B28: =$B$27-Impresa_guida!$B$24 -> 0 | C28: euro | D28: 0 | E28: =IF(ABS(B28-D28)<=0.5,"OK","DIVERSO") -> OK | F28: capitolo 5
A30: Piano dei centri - commerciali e logistici
A31: Tre centri che servono i clienti, con il volume della loro misura di attività; capitolo 5
A32: Voce | B32: Valore | C32: Unità | D32: Valore atteso (libro) | E32: Controllo | F32: Fonte nel libro
A33: Gestione ordini | B33: =Cap_02!$B$20 -> 240000 | C33: euro | F33: capitolo 5
A34: Gestione ordini - numero ordini | B34: 12000 | C34: ordini | F34: capitolo 5
A35: Consegne | B35: =Cap_02!$B$23 -> 180000 | C35: euro | F35: capitolo 5
A36: Consegne - numero consegne | B36: 6000 | C36: consegne | F36: capitolo 5
A37: Assistenza tecnica | B37: =Cap_02!$B$26 -> 150000 | C37: euro | F37: capitolo 5
A38: Assistenza tecnica - ore di assistenza | B38: 7500 | C38: ore | F38: capitolo 5
A39: Totale centri commerciali e logistici | B39: =$B$33+$B$35+$B$37 -> 570000 | C39: euro | D39: 570000 | E39: =IF(ABS(B39-D39)<=0.5,"OK","DIVERSO") -> OK | F39: capitolo 5
A40: Controllo con le attività commerciali e logistiche | B40: =$B$39-Impresa_guida!$B$23 -> 0 | C40: euro | D40: 0 | E40: =IF(ABS(B40-D40)<=0.5,"OK","DIVERSO") -> OK | F40: paragrafo 19.3
A42: Piano dei centri - struttura
A43: Amministrazione: centro di struttura in gestione separata, non ripartito; capitolo 5
A44: Voce | B44: Valore | C44: Unità | D44: Valore atteso (libro) | E44: Controllo | F44: Fonte nel libro
...

Sheet Cap_06
A1: Capitolo 6 - Costi diretti, indiretti e allocazione
A2: Controllo di gestione con l'intelligenza artificiale - file Excel che accompagna il libro
A3: Celle blu su fondo giallo: dati da cambiare. Celle nere: formule. «Valore atteso (libro)» e «Controllo» confrontano il calcolo con il numero stampato nel libro.
A4: Coefficienti di allocazione, ribaltamento dei centri ausiliari con tre metodi e allocazione dei costi indiretti dell'impresa guida sulle ore e sulle unità.
A6: Coefficiente di allocazione
A7: Coefficiente = costi del centro / volume della base; costo allocato = coefficiente x base; capitolo 6
A8: Voce | B8: Valore | C8: Unità | D8: Valore atteso (libro) | E8: Controllo | F8: Fonte nel libro
A9: Costi del centro produttivo | B9: 240000 | C9: euro | F9: capitolo 6
A10: Ore macchina previste | B10: 12000 | C10: ore | F10: capitolo 6
A11: Coefficiente | B11: =$B$9/$B$10 -> 20 | C11: euro/ora | D11: 20 | E11: =IF(ABS(B11-D11)<=0.005,"OK","DIVERSO") -> OK | F11: capitolo 6
A12: Ore usate dal prodotto | B12: 150 | C12: ore | F12: capitolo 6
A13: Costo allocato al prodotto | B13: =$B$11*$B$12 -> 3000 | C13: euro | D13: 3000 | E13: =IF(ABS(B13-D13)<=0.5,"OK","DIVERSO") -> OK | F13: capitolo 6
A15: Tre metodi - dati
A16: Stabilimento con due ausiliari che si servono a vicenda: costi propri e percentuali di servizio; capitolo 6
A17: Voce | B17: Valore | C17: Unità | D17: Valore atteso (libro) | E17: Controllo | F17: Fonte nel libro
A18: Manutenzione - costi propri | B18: 50000 | C18: euro | F18: capitolo 6
A19: Servizi energetici - costi propri | B19: 35000 | C19: euro | F19: capitolo 6
A20: Lavorazione - costi propri | B20: 180000 | C20: euro | F20: capitolo 6
A21: Assemblaggio - costi propri | B21: 120000 | C21: euro | F21: capitolo 6
A22: Totale costi propri | B22: =$B$18+$B$19+$B$20+$B$21 -> 385000 | C22: euro | D22: 385000 | E22: =IF(ABS(B22-D22)<=0.5,"OK","DIVERSO") -> OK | F22: capitolo 6
A23: Manutenzione a Servizi energetici | B23: 0.25 | C23: % | F23: capitolo 6
A24: Manutenzione a Lavorazione | B24: 0.45 | C24: % | F24: capitolo 6
A25: Manutenzione ad Assemblaggio | B25: 0.3 | C25: % | F25: capitolo 6
A26: Servizi energetici a Manutenzione | B26: 0.2 | C26: % | F26: capitolo 6
A27: Servizi energetici a Lavorazione | B27: 0.2 | C27: % | F27: capitolo 6
A28: Servizi energetici ad Assemblaggio | B28: 0.6 | C28: % | F28: capitolo 6
A30: Metodo diretto
A31: Scambi fra ausiliari ignorati, percentuali ricalcolate sui soli produttivi; capitolo 6
A32: Voce | B32: Valore | C32: Unità | D32: Valore atteso (libro) | E32: Controllo | F32: Fonte nel libro
A33: Manutenzione - quota Lavorazione | B33: =$B$24/($B$24+$B$25) -> 0.6 | C33: % | D33: 0.6 | E33: =IF(ABS(B33-D33)<=0.0005,"OK","DIVERSO") -> OK | F33: capitolo 6
A34: Manutenzione - quota Assemblaggio | B34: =$B$25/($B$24+$B$25) -> 0.4 | C34: % | D34: 0.4 | E34: =IF(ABS(B34-D34)<=0.0005,"OK","DIVERSO") -> OK | F34: capitolo 6
A35: Manutenzione a Lavorazione | B35: =$B$18*$B$33 -> 30000 | C35: euro | D35: 30000 | E35: =IF(ABS(B35-D35)<=0.5,"OK","DIVERSO") -> OK | F35: capitolo 6
A36: Manutenzione ad Assemblaggio | B36: =$B$18*$B$34 -> 20000 | C36: euro | D36: 20000 | E36: =IF(ABS(B36-D36)<=0.5,"OK","DIVERSO") -> OK | F36: capitolo 6
A37: Servizi energetici - quota Lavorazione | B37: =$B$27/($B$27+$B$28) -> 0.25 | C37: % | D37: 0.25 | E37: =IF(ABS(B37-D37)<=0.0005,"OK","DIVERSO") -> OK | F37: capitolo 6
A38: Servizi energetici - quota Assemblaggio | B38: =$B$28/($B$27+$B$28) -> 0.75 | C38: % | D38: 0.75 | E38: =IF(ABS(B38-D38)<=0.0005,"OK","DIVERSO") -> OK | F38: capitolo 6
A39: Servizi energetici a Lavorazione | B39: =$B$19*$B$37 -> 8750 | C39: euro | D39: 8750 | E39: =IF(ABS(B39-D39)<=0.5,"OK","DIVERSO") -> OK | F39: capitolo 6
A40: Servizi energetici ad Assemblaggio | B40: =$B$19*$B$38 -> 26250 | C40: euro | D40: 26250 | E40: =IF(ABS(B40-D40)<=0.5,"OK","DIVERSO") -> OK | F40: capitolo 6
A41: Lavorazione dopo il metodo diretto | B41: =$B$20+$B$35+$B$39 -> 218750 | C41: euro | D41: 218750 | E41: =IF(ABS(B41-D41)<=0.5,"OK","DIVERSO") -> OK | F41: capitolo 6
A42: Assemblaggio dopo il metodo diretto | B42: =$B$21+$B$36+$B$40 -> 166250 | C42: euro | D42: 166250 | E42: =IF(ABS(B42-D42)<=0.5,"OK","DIVERSO") -> OK | F42: capitolo 6
A43: Totale dopo il metodo diretto | B43: =$B$41+$B$42 -> 385000 | C43: euro | D43: 385000 | E43: =IF(ABS(B43-D43)<=0.5,"OK","DIVERSO") -> OK | F43: capitolo 6
...

Sheet Cap_07
A1: Capitolo 7 - Full Costing
A2: Controllo di gestione con l'intelligenza artificiale - file Excel che accompagna il libro
A3: Celle blu su fondo giallo: dati da cambiare. Celle nere: formule. «Valore atteso (libro)» e «Controllo» confrontano il calcolo con il numero stampato nel libro.
A4: Configurazioni progressive di costo e costo pieno complessivo delle tre linee dell'impresa guida, riconciliato con il risultato operativo.
A6: Configurazioni progressive
A7: Costo primo, industriale e complessivo per strati; capitolo 7
A8: Voce | B8: Valore | C8: Unità | D8: Valore atteso (libro) | E8: Controllo | F8: Fonte nel libro
A9: Materiali diretti | B9: 45 | C9: euro/unità | F9: capitolo 7
A10: Lavoro diretto | B10: 25 | C10: euro/unità | F10: capitolo 7
A11: Indiretti di produzione | B11: 18 | C11: euro/unità | F11: capitolo 7
A12: Commerciali e amministrativi | B12: 12 | C12: euro/unità | F12: capitolo 7
A13: Costo primo | B13: =$B$9+$B$10 -> 70 | C13: euro/unità | D13: 70 | E13: =IF(ABS(B13-D13)<=0.5,"OK","DIVERSO") -> OK | F13: capitolo 7
A14: Costo industriale | B14: =$B$13+$B$11 -> 88 | C14: euro/unità | D14: 88 | E14: =IF(ABS(B14-D14)<=0.5,"OK","DIVERSO") -> OK | F14: capitolo 7
A15: Costo complessivo | B15: =$B$14+$B$12 -> 100 | C15: euro/unità | D15: 100 | E15: =IF(ABS(B15-D15)<=0.5,"OK","DIVERSO") -> OK | F15: capitolo 7
A17: Redditività a costo pieno
A18: Due prodotti: costo pieno e margine pieno unitario; capitolo 7
A19: Voce | B19: Valore | C19: Unità | D19: Valore atteso (libro) | E19: Controllo | F19: Fonte nel libro
A20: Prodotto A - prezzo netto | B20: 140 | C20: euro/unità | F20: capitolo 7
A21: Prodotto A - costi diretti | B21: 65 | C21: euro/unità | F21: capitolo 7
A22: Prodotto A - indiretti allocati | B22: 35 | C22: euro/unità | F22: capitolo 7
A23: Prodotto A - costo pieno | B23: =$B$21+$B$22 -> 100 | C23: euro/unità | D23: 100 | E23: =IF(ABS(B23-D23)<=0.5,"OK","DIVERSO") -> OK | F23: capitolo 7
A24: Prodotto A - margine pieno | B24: =$B$20-$B$23 -> 40 | C24: euro/unità | D24: 40 | E24: =IF(ABS(B24-D24)<=0.5,"OK","DIVERSO") -> OK | F24: capitolo 7
A25: Prodotto B - prezzo netto | B25: 110 | C25: euro/unità | F25: capitolo 7
A26: Prodotto B - costi diretti | B26: 50 | C26: euro/unità | F26: capitolo 7
A27: Prodotto B - indiretti allocati | B27: 45 | C27: euro/unità | F27: capitolo 7
A28: Prodotto B - costo pieno | B28: =$B$26+$B$27 -> 95 | C28: euro/unità | D28: 95 | E28: =IF(ABS(B28-D28)<=0.5,"OK","DIVERSO") -> OK | F28: capitolo 7
A29: Prodotto B - margine pieno | B29: =$B$25-$B$28 -> 15 | C29: euro/unità | D29: 15 | E29: =IF(ABS(B29-D29)<=0.5,"OK","DIVERSO") -> OK | F29: capitolo 7
A31: Impresa guida - struttura da ripartire
A32: Struttura meno indiretti di produzione, ripartita in proporzione ai ricavi; capitolo 7
A33: Voce | B33: Valore | C33: Unità | D33: Valore atteso (libro) | E33: Controllo | F33: Fonte nel libro
A34: Struttura da ripartire (con la capacità esterna) | B34: =Impresa_guida!$B$41-Cap_06!$B$115 -> 700000 | C34: euro | D34: 700000 | E34: =IF(ABS(B34-D34)<=0.5,"OK","DIVERSO") -> OK | F34: capitolo 7
A35: Quota di struttura linea A | B35: =$B$34*Impresa_guida!$B$31/Impresa_guida!$B$34 -> 297696.4 | C35: euro | D35: 297696 | E35: =IF(ABS(B35-D35)<=0.5,"OK","DIVERSO") -> OK | F35: capitolo 7
A36: Quota di struttura linea B | B36: =$B$34*Impresa_guida!$B$32/Impresa_guida!$B$34 -> 282811.58 | C36: euro | D36: 282812 | E36: =IF(ABS(B36-D36)<=0.5,"OK","DIVERSO") -> OK | F36: capitolo 7
A37: Quota di struttura linea C | B37: =$B$34*Impresa_guida!$B$33/Impresa_guida!$B$34 -> 119492.03 | C37: euro | D37: 119492 | E37: =IF(ABS(B37-D37)<=0.5,"OK","DIVERSO") -> OK | F37: capitolo 7
A38: Totale quote di struttura | B38: =$B$35+$B$36+$B$37 -> 700000 | C38: euro | D38: 700000 | E38: =IF(ABS(B38-D38)<=0.5,"OK","DIVERSO") -> OK | F38: capitolo 7
A40: Impresa guida - costo pieno per unità
A41: Strati per unità: costo variabile, indiretti sulle ore, quota di struttura; capitolo 7
A42: Voce | B42: Valore | C42: Unità | D42: Valore atteso (libro) | E42: Controllo | F42: Fonte nel libro
A43: Linea A - indiretti di produzione | B43: =Cap_06!$B$131 -> 7.5 | C43: euro/unità | D43: 7.5 | E43: =IF(ABS(B43-D43)<=0.005,"OK","DIVERSO") -> OK | F43: capitolo 7
A44: Linea A - costo industriale | B44: =Impresa_guida!$B$10+$B$43 -> 124.5 | C44: euro/unità | D44: 124.5 | E44: =IF(ABS(B44-D44)<=0.005,"OK","DIVERSO") -> OK | F44: capitolo 7
...

Sheet Cap_08
A1: Capitolo 8 - Direct Costing e margine di contribuzione
A2: Controllo di gestione con l'intelligenza artificiale - file Excel che accompagna il libro
A3: Celle blu su fondo giallo: dati da cambiare. Celle nere: formule. «Valore atteso (libro)» e «Controllo» confrontano il calcolo con il numero stampato nel libro.
A4: Margine di contribuzione unitario, totale e percentuale, secondo margine e prospetto a margine dell'impresa guida per linea e per canale.
A6: Margine unitario e percentuale
A7: Tre prodotti: margine = prezzo - costo variabile e margine percentuale; capitolo 8
A8: Voce | B8: Valore | C8: Unità | D8: Valore atteso (libro) | E8: Controllo | F8: Fonte nel libro
A9: Prodotto A - prezzo | B9: 100 | C9: euro/unità | F9: capitolo 8
A10: Prodotto A - costo variabile | B10: 60 | C10: euro/unità | F10: capitolo 8
A11: Prodotto A - margine | B11: =$B$9-$B$10 -> 40 | C11: euro/unità | D11: 40 | E11: =IF(ABS(B11-D11)<=0.5,"OK","DIVERSO") -> OK | F11: capitolo 8
A12: Prodotto A - margine percentuale | B12: =$B$11/$B$9 -> 0.4 | C12: % | D12: 0.4 | E12: =IF(ABS(B12-D12)<=0.0005,"OK","DIVERSO") -> OK | F12: capitolo 8
A13: Prodotto B - prezzo | B13: 70 | C13: euro/unità | F13: capitolo 8
A14: Prodotto B - costo variabile | B14: 35 | C14: euro/unità | F14: capitolo 8
A15: Prodotto B - margine | B15: =$B$13-$B$14 -> 35 | C15: euro/unità | D15: 35 | E15: =IF(ABS(B15-D15)<=0.5,"OK","DIVERSO") -> OK | F15: capitolo 8
A16: Prodotto B - margine percentuale | B16: =$B$15/$B$13 -> 0.5 | C16: % | D16: 0.5 | E16: =IF(ABS(B16-D16)<=0.0005,"OK","DIVERSO") -> OK | F16: capitolo 8
A17: Prodotto C - prezzo | B17: 150 | C17: euro/unità | F17: capitolo 8
A18: Prodotto C - costo variabile | B18: 105 | C18: euro/unità | F18: capitolo 8
A19: Prodotto C - margine | B19: =$B$17-$B$18 -> 45 | C19: euro/unità | D19: 45 | E19: =IF(ABS(B19-D19)<=0.5,"OK","DIVERSO") -> OK | F19: capitolo 8
A20: Prodotto C - margine percentuale | B20: =$B$19/$B$17 -> 0.3 | C20: % | D20: 0.3 | E20: =IF(ABS(B20-D20)<=0.0005,"OK","DIVERSO") -> OK | F20: capitolo 8
A22: Conto Economico a margine
A23: Primo margine, secondo margine e risultato operativo; capitolo 8
A24: Voce | B24: Valore | C24: Unità | D24: Valore atteso (libro) | E24: Controllo | F24: Fonte nel libro
A25: Ricavi | B25: 500000 | C25: euro | F25: capitolo 8
A26: Costi variabili | B26: 300000 | C26: euro | F26: capitolo 8
A27: Costi fissi specifici | B27: 70000 | C27: euro | F27: capitolo 8
A28: Costi fissi comuni | B28: 90000 | C28: euro | F28: capitolo 8
A29: Margine di contribuzione | B29: =$B$25-$B$26 -> 200000 | C29: euro | D29: 200000 | E29: =IF(ABS(B29-D29)<=0.5,"OK","DIVERSO") -> OK | F29: capitolo 8
A30: Secondo margine | B30: =$B$29-$B$27 -> 130000 | C30: euro | D30: 130000 | E30: =IF(ABS(B30-D30)<=0.5,"OK","DIVERSO") -> OK | F30: capitolo 8
A31: Risultato operativo | B31: =$B$30-$B$28 -> 40000 | C31: euro | D31: 40000 | E31: =IF(ABS(B31-D31)<=0.5,"OK","DIVERSO") -> OK | F31: capitolo 8
A33: Margini per cliente
A34: Cliente Z: margine di prodotto, dopo i costi di servizio e secondo margine; capitolo 8
A35: Voce | B35: Valore | C35: Unità | D35: Valore atteso (libro) | E35: Controllo | F35: Fonte nel libro
A36: Ricavi netti | B36: 250000 | C36: euro | F36: capitolo 8
A37: Costi variabili prodotto | B37: 145000 | C37: euro | F37: capitolo 8
A38: Logistica, gestione dei resi e assistenza | B38: 32000 | C38: euro | F38: capitolo 8
A39: Costi fissi specifici | B39: 18000 | C39: euro | F39: capitolo 8
A40: Margine di prodotto | B40: =$B$36-$B$37 -> 105000 | C40: euro | D40: 105000 | E40: =IF(ABS(B40-D40)<=0.5,"OK","DIVERSO") -> OK | F40: capitolo 8
A41: Margine dopo i costi variabili di servizio | B41: =$B$40-$B$38 -> 73000 | C41: euro | D41: 73000 | E41: =IF(ABS(B41-D41)<=0.5,"OK","DIVERSO") -> OK | F41: capitolo 8
A42: Secondo margine | B42: =$B$41-$B$39 -> 55000 | C42: euro | D42: 55000 | E42: =IF(ABS(B42-D42)<=0.5,"OK","DIVERSO") -> OK | F42: capitolo 8
A44: Impresa guida - prospetto a margine
...

Sheet Cap_09
A1: Capitolo 9 - Break-even e analisi costo-volume-risultato
A2: Controllo di gestione con l'intelligenza artificiale - file Excel che accompagna il libro
A3: Celle blu su fondo giallo: dati da cambiare. Celle nere: formule. «Valore atteso (libro)» e «Controllo» confrontano il calcolo con il numero stampato nel libro.
A4: Pareggio in unità e fatturato, utile obiettivo, margine di sicurezza, leva operativa, mix e sensibilità, poi il pareggio a tratti dell'impresa guida.
A6: Pareggio in unità - esempio base
A7: Pareggio con prezzo 100, costo variabile 60 e costi fissi 200.000, con la verifica al pareggio; capitolo 9
A8: Voce | B8: Valore | C8: Unità | D8: Valore atteso (libro) | E8: Controllo | F8: Fonte nel libro
A9: Prezzo unitario | B9: 100 | C9: euro/unità | F9: capitolo 9
A10: Costo variabile unitario | B10: 60 | C10: euro/unità | F10: capitolo 9
A11: Costi fissi | B11: 200000 | C11: euro | F11: capitolo 9
A12: Margine di contribuzione unitario | B12: =$B$9-$B$10 -> 40 | C12: euro/unità | D12: 40 | E12: =IF(ABS(B12-D12)<=0.5,"OK","DIVERSO") -> OK | F12: capitolo 9
A13: Pareggio in unità | B13: =ROUNDUP($B$11/$B$12,0) -> 5000 | C13: unità | D13: 5000 | E13: =IF(ABS(B13-D13)<=0.5,"OK","DIVERSO") -> OK | F13: capitolo 9
A14: Ricavi al pareggio | B14: =$B$13*$B$9 -> 500000 | C14: euro | D14: 500000 | E14: =IF(ABS(B14-D14)<=0.5,"OK","DIVERSO") -> OK | F14: capitolo 9
A15: Costi variabili al pareggio | B15: =$B$13*$B$10 -> 300000 | C15: euro | D15: 300000 | E15: =IF(ABS(B15-D15)<=0.5,"OK","DIVERSO") -> OK | F15: capitolo 9
A16: Margine al pareggio | B16: =$B$13*$B$12 -> 200000 | C16: euro | D16: 200000 | E16: =IF(ABS(B16-D16)<=0.5,"OK","DIVERSO") -> OK | F16: capitolo 9
A17: Risultato al pareggio | B17: =$B$16-$B$11 -> 0 | C17: euro | D17: 0 | E17: =IF(ABS(B17-D17)<=0.5,"OK","DIVERSO") -> OK | F17: capitolo 9
A19: Arrotondamento per eccesso
A20: Con margine 35 la divisione non è intera: a 5.714 unità si è ancora in perdita, il pareggio è 5.715; capitolo 9
A21: Voce | B21: Valore | C21: Unità | D21: Valore atteso (libro) | E21: Controllo | F21: Fonte nel libro
A22: Margine unitario dell'esempio | B22: 35 | C22: euro/unità | F22: capitolo 9
A23: Costi fissi / margine (non arrotondato) | B23: =$B$11/$B$22 -> 5714.2857 | C23: unità | D23: 5714.3 | E23: =IF(ABS(B23-D23)<=0.05,"OK","DIVERSO") -> OK | F23: capitolo 9
A24: Unità arrotondate per difetto | B24: =ROUNDDOWN($B$23,0) -> 5714 | C24: unità | D24: 5714 | E24: =IF(ABS(B24-D24)<=0.5,"OK","DIVERSO") -> OK | F24: capitolo 9
A25: Margine totale a 5.714 unità | B25: =$B$24*$B$22 -> 199990 | C25: euro | D25: 199990 | E25: =IF(ABS(B25-D25)<=0.5,"OK","DIVERSO") -> OK | F25: capitolo 9
A26: Risultato a 5.714 unità | B26: =$B$25-$B$11 -> -10 | C26: euro | D26: -10 | E26: =IF(ABS(B26-D26)<=0.5,"OK","DIVERSO") -> OK | F26: capitolo 9
A27: Pareggio in unità (per eccesso) | B27: =ROUNDUP($B$23,0) -> 5715 | C27: unità | D27: 5715 | E27: =IF(ABS(B27-D27)<=0.5,"OK","DIVERSO") -> OK | F27: capitolo 9
A28: Risultato a 5.715 unità | B28: =$B$27*$B$22-$B$11 -> 25 | C28: euro | D28: 25 | E28: =IF(ABS(B28-D28)<=0.5,"OK","DIVERSO") -> OK | F28: capitolo 9
A30: Pareggio in fatturato
A31: Pareggio espresso in fatturato con il margine percentuale; capitolo 9
A32: Voce | B32: Valore | C32: Unità | D32: Valore atteso (libro) | E32: Controllo | F32: Fonte nel libro
A33: Margine percentuale | B33: =$B$12/$B$9 -> 0.4 | C33: % | D33: 0.4 | E33: =IF(ABS(B33-D33)<=0.0005,"OK","DIVERSO") -> OK | F33: capitolo 9
A34: Fatturato di pareggio | B34: =$B$11/$B$33 -> 500000 | C34: euro | D34: 500000 | E34: =IF(ABS(B34-D34)<=0.5,"OK","DIVERSO") -> OK | F34: capitolo 9
A36: Utile obiettivo
A37: Volume per un utile obiettivo, anche partendo da un utile netto dopo imposte; capitolo 9
A38: Voce | B38: Valore | C38: Unità | D38: Valore atteso (libro) | E38: Controllo | F38: Fonte nel libro
A39: Utile obiettivo (risultato operativo) | B39: 80000 | C39: euro | F39: capitolo 9
A40: Volume per utile obiettivo | B40: =ROUNDUP(($B$11+$B$39)/$B$12,0) -> 7000 | C40: unità | D40: 7000 | E40: =IF(ABS(B40-D40)<=0.5,"OK","DIVERSO") -> OK | F40: capitolo 9
A41: Utile netto desiderato | B41: 56000 | C41: euro | F41: capitolo 9
A42: Aliquota prevista | B42: 0.3 | C42: % | F42: capitolo 9
A43: Oneri finanziari | B43: 0 | C43: euro | F43: capitolo 9
A44: Risultato operativo necessario | B44: =$B$41/(1-$B$42)+$B$43 -> 80000 | C44: euro | D44: 80000 | E44: =IF(ABS(B44-D44)<=0.5,"OK","DIVERSO") -> OK | F44: capitolo 9
...

Sheet Cap_10
A1: Capitolo 10 - Activity Based Costing
A2: Controllo di gestione con l'intelligenza artificiale - file Excel che accompagna il libro
A3: Celle blu su fondo giallo: dati da cambiare. Celle nere: formule. «Valore atteso (libro)» e «Controllo» confrontano il calcolo con il numero stampato nel libro.
A4: Le due fasi dell'ABC sull'esempio illustrativo, il TDABC, il confronto con il sistema tradizionale e il modello per canale dell'impresa guida.
A6: Risorse da ripartire
A7: Le quattro risorse che alimentano le attività dell'esempio illustrativo; capitolo 10
A8: Voce | B8: Valore | C8: Unità | D8: Valore atteso (libro) | E8: Controllo | F8: Fonte nel libro
A9: Personale indiretto | B9: 480000 | C9: euro | F9: capitolo 10
A10: Ammortamenti e manutenzioni attrezzature | B10: 150000 | C10: euro | F10: capitolo 10
A11: Sistemi informativi | B11: 90000 | C11: euro | F11: capitolo 10
A12: Metri quadrati occupati | B12: 1200 | C12: metri quadrati | F12: capitolo 10
A13: Costo per metro quadrato | B13: 50 | C13: euro/metro quadrato | F13: capitolo 10
A14: Spazi | B14: =$B$12*$B$13 -> 60000 | C14: euro | D14: 60000 | E14: =IF(ABS(B14-D14)<=0.5,"OK","DIVERSO") -> OK | F14: capitolo 10
A15: Totale risorse | B15: =$B$9+$B$10+$B$11+$B$14 -> 780000 | C15: euro | D15: 780000 | E15: =IF(ABS(B15-D15)<=0.5,"OK","DIVERSO") -> OK | F15: capitolo 10
A17: Prima fase - personale e attrezzature
A18: Ripartizione di personale (quote di tempo) e attrezzature (utilizzo) sulle attività; capitolo 10
A19: Voce | B19: Valore | C19: Unità | D19: Valore atteso (libro) | E19: Controllo | F19: Fonte nel libro
A20: Personale - quota attrezzaggi | B20: 0.25 | C20: % | F20: capitolo 10
A21: Personale - quota gestione ordini | B21: 0.35 | C21: % | F21: capitolo 10
A22: Personale - quota controllo qualità | B22: 0.15 | C22: % | F22: capitolo 10
A23: Personale - quota assistenza | B23: 0.25 | C23: % | F23: capitolo 10
A24: Personale - a attrezzaggi | B24: =$B$9*$B$20 -> 120000 | C24: euro | D24: 120000 | E24: =IF(ABS(B24-D24)<=0.5,"OK","DIVERSO") -> OK | F24: capitolo 10
A25: Personale - a gestione ordini | B25: =$B$9*$B$21 -> 168000 | C25: euro | D25: 168000 | E25: =IF(ABS(B25-D25)<=0.5,"OK","DIVERSO") -> OK | F25: capitolo 10
A26: Personale - a controllo qualità | B26: =$B$9*$B$22 -> 72000 | C26: euro | D26: 72000 | E26: =IF(ABS(B26-D26)<=0.5,"OK","DIVERSO") -> OK | F26: capitolo 10
A27: Personale - a assistenza | B27: =$B$9*$B$23 -> 120000 | C27: euro | D27: 120000 | E27: =IF(ABS(B27-D27)<=0.5,"OK","DIVERSO") -> OK | F27: capitolo 10
A28: Personale - totale ripartito | B28: =$B$24+$B$25+$B$26+$B$27 -> 480000 | C28: euro | D28: 480000 | E28: =IF(ABS(B28-D28)<=0.5,"OK","DIVERSO") -> OK | F28: capitolo 10
A29: Attrezzature - quota attrezzaggi | B29: 0.3 | C29: % | F29: capitolo 10
A30: Attrezzature - quota gestione ordini | B30: 0 | C30: % | F30: capitolo 10
A31: Attrezzature - quota controllo qualità | B31: 0.4 | C31: % | F31: capitolo 10
A32: Attrezzature - quota assistenza | B32: 0.3 | C32: % | F32: capitolo 10
A33: Attrezzature - a attrezzaggi | B33: =$B$10*$B$29 -> 45000 | C33: euro | D33: 45000 | E33: =IF(ABS(B33-D33)<=0.5,"OK","DIVERSO") -> OK | F33: capitolo 10
A34: Attrezzature - a gestione ordini | B34: =$B$10*$B$30 -> 0 | C34: euro | D34: 0 | E34: =IF(ABS(B34-D34)<=0.5,"OK","DIVERSO") -> OK | F34: capitolo 10
A35: Attrezzature - a controllo qualità | B35: =$B$10*$B$31 -> 60000 | C35: euro | D35: 60000 | E35: =IF(ABS(B35-D35)<=0.5,"OK","DIVERSO") -> OK | F35: capitolo 10
A36: Attrezzature - a assistenza | B36: =$B$10*$B$32 -> 45000 | C36: euro | D36: 45000 | E36: =IF(ABS(B36-D36)<=0.5,"OK","DIVERSO") -> OK | F36: capitolo 10
A37: Attrezzature - totale ripartito | B37: =$B$33+$B$34+$B$35+$B$36 -> 150000 | C37: euro | D37: 150000 | E37: =IF(ABS(B37-D37)<=0.5,"OK","DIVERSO") -> OK | F37: capitolo 10
A39: Prima fase - sistemi e spazi
A40: Ripartizione di sistemi (transazioni) e spazi (metri quadrati) sulle attività; capitolo 10
A41: Voce | B41: Valore | C41: Unità | D41: Valore atteso (libro) | E41: Controllo | F41: Fonte nel libro
A42: Sistemi - quota attrezzaggi | B42: 0.05 | C42: % | F42: capitolo 10
A43: Sistemi - quota gestione ordini | B43: 0.5 | C43: % | F43: capitolo 10
...

Sheet Cap_11
A1: Capitolo 11 - Activity Based Management
A2: Controllo di gestione con l'intelligenza artificiale - file Excel che accompagna il libro
A3: Celle blu su fondo giallo: dati da cambiare. Celle nere: formule. «Valore atteso (libro)» e «Controllo» confrontano il calcolo con il numero stampato nel libro.
A4: Capacità fornita e utilizzata, costo di servizio dei clienti X e Y e leve che separano la minore spesa dalla capacità liberata.
A6: Capacità fornita e utilizzata
A7: Team che può gestire 10.000 ordini e ne gestisce 8.000; capitolo 11
A8: Voce | B8: Valore | C8: Unità | D8: Valore atteso (libro) | E8: Controllo | F8: Fonte nel libro
A9: Ordini gestibili (capacità fornita) | B9: 10000 | C9: ordini | F9: capitolo 11
A10: Ordini gestiti (capacità utilizzata) | B10: 8000 | C10: ordini | F10: capitolo 11
A11: Capacità inutilizzata | B11: =$B$9-$B$10 -> 2000 | C11: ordini | F11: capitolo 11
A12: Quota di capacità inutilizzata | B12: =$B$11/$B$9 -> 0.2 | C12: % | F12: capitolo 11
A14: Impresa guida - natura dei pool
A15: Parte di ciascun pool che varia con il driver e parte che è costo di capacità; capitolo 11
A16: Voce | B16: Valore | C16: Unità | D16: Valore atteso (libro) | E16: Controllo | F16: Fonte nel libro
A17: Gestione ordini - costo variabile per ordine | B17: 0 | C17: euro/ordine | F17: capitolo 11
A18: Gestione ordini - costo di capacità | B18: =Cap_10!$B$131-$B$17*Cap_10!$B$146 -> 240000 | C18: euro | D18: 240000 | E18: =IF(ABS(B18-D18)<=0.5,"OK","DIVERSO") -> OK | F18: capitolo 11
A19: Consegne - trasporti per consegna | B19: =Cap_10!$B$132/Cap_10!$B$147 -> 23 | C19: euro/consegna | D19: 23 | E19: =IF(ABS(B19-D19)<=0.5,"OK","DIVERSO") -> OK | F19: capitolo 11
A20: Consegne - personale per consegna (capacità) | B20: =Cap_10!$B$133/Cap_10!$B$147 -> 7 | C20: euro/consegna | D20: 7 | E20: =IF(ABS(B20-D20)<=0.5,"OK","DIVERSO") -> OK | F20: capitolo 11
A21: Variabile più capacità meno tariffa | B21: =$B$19+$B$20-Cap_10!$B$150 -> 0 | C21: euro/consegna | D21: 0 | E21: =IF(ABS(B21-D21)<=0.5,"OK","DIVERSO") -> OK | F21: capitolo 11
A22: Assistenza - costo di capacità | B22: =Cap_10!$B$135 -> 118000 | C22: euro | D22: 118000 | E22: =IF(ABS(B22-D22)<=0.5,"OK","DIVERSO") -> OK | F22: capitolo 11
A23: Assistenza - ricambi e trasferte | B23: 32.000 euro variano con le ore di intervento tecnico, non con tutte le 7.500 ore (capitolo 11)
A25: Impresa guida - clienti X e Y
A26: Costo di servizio a tariffa e margine cliente di CL-014 e CL-027; capitolo 11
A27: Voce | B27: Valore | C27: Unità | D27: Valore atteso (libro) | E27: Controllo | F27: Fonte nel libro
A28: Ricavi di ciascun cliente | B28: 240000 | C28: euro | F28: capitolo 11
A29: Margine di prodotto di ciascun cliente | B29: 84000 | C29: euro | F29: capitolo 11
A30: X - ordini | B30: 600 | C30: ordini | F30: capitolo 11
A31: X - consegne | B31: 300 | C31: consegne | F31: capitolo 11
A32: X - ore di assistenza | B32: 250 | C32: ore | F32: capitolo 11
A33: X - costo di servizio | B33: =$B$30*Cap_10!$B$149+$B$31*Cap_10!$B$150+$B$32*Cap_10!$B$151 -> 26000 | C33: euro | D33: 26000 | E33: =IF(ABS(B33-D33)<=0.5,"OK","DIVERSO") -> OK | F33: capitolo 11
A34: X - margine cliente | B34: =$B$29-$B$33 -> 58000 | C34: euro | D34: 58000 | E34: =IF(ABS(B34-D34)<=0.5,"OK","DIVERSO") -> OK | F34: capitolo 11
A35: X - margine cliente % | B35: =$B$34/$B$28 -> 0.24166667 | C35: % | D35: 0.242 | E35: =IF(ABS(B35-D35)<=0.0005,"OK","DIVERSO") -> OK | F35: capitolo 11
A36: Y - ordini | B36: 150 | C36: ordini | F36: capitolo 11
A37: Y - consegne | B37: 60 | C37: consegne | F37: capitolo 11
A38: Y - ore di assistenza | B38: 40 | C38: ore | F38: capitolo 11
A39: Y - costo di servizio | B39: =$B$36*Cap_10!$B$149+$B$37*Cap_10!$B$150+$B$38*Cap_10!$B$151 -> 5600 | C39: euro | D39: 5600 | E39: =IF(ABS(B39-D39)<=0.5,"OK","DIVERSO") -> OK | F39: capitolo 11
A40: Y - margine cliente | B40: =$B$29-$B$39 -> 78400 | C40: euro | D40: 78400 | E40: =IF(ABS(B40-D40)<=0.5,"OK","DIVERSO") -> OK | F40: capitolo 11
A41: Y - margine cliente % | B41: =$B$40/$B$28 -> 0.32666667 | C41: % | D41: 0.327 | E41: =IF(ABS(B41-D41)<=0.0005,"OK","DIVERSO") -> OK | F41: capitolo 11
A43: Impresa guida - leve su X
A44: Ordini da 600 a 300 e consegne da 300 a 24: riduzione a tariffa, minore spesa e capacità liberata; capitolo 11
...

Sheet Cap_12
A1: Capitolo 12 - Budget
A2: Controllo di gestione con l'intelligenza artificiale - file Excel che accompagna il libro
A3: Celle blu su fondo giallo: dati da cambiare. Celle nere: formule. «Valore atteso (libro)» e «Controllo» confrontano il calcolo con il numero stampato nel libro.
A4: Il budget dell'impresa guida dall'esercizio corrente, separato in run rate, driver e iniziative, con la sensibilità sul recupero di prezzo della linea B.
A6: Esercizio corrente (run rate)
A7: Valori di chiusura dell'esercizio corrente dal foglio Impresa_guida; capitolo 12, tabella
A8: Voce | B8: Valore | C8: Unità | D8: Valore atteso (libro) | E8: Controllo | F8: Fonte nel libro
A9: Risultato operativo esercizio corrente | B9: =Impresa_guida!$B$36-Impresa_guida!$B$41 -> 242000 | C9: euro | D9: 242000 | E9: =IF(ABS(B9-D9)<=0.5,"OK","DIVERSO") -> OK | F9: capitolo 12
A10: Margine unitario corrente linea A | B10: =Impresa_guida!$B$9-Impresa_guida!$B$10 -> 63 | C10: euro/unità | D10: 63 | E10: =IF(ABS(B10-D10)<=0.5,"OK","DIVERSO") -> OK | F10: capitolo 14
A11: Margine unitario corrente linea B | B11: =Impresa_guida!$B$13-Impresa_guida!$B$14 -> 38 | C11: euro/unità | D11: 38 | E11: =IF(ABS(B11-D11)<=0.5,"OK","DIVERSO") -> OK | F11: capitolo 12
A12: Margine unitario corrente linea C | B12: =Impresa_guida!$B$17-Impresa_guida!$B$18 -> 51 | C12: euro/unità | D12: 51 | E12: =IF(ABS(B12-D12)<=0.5,"OK","DIVERSO") -> OK | F12: capitolo 12
A14: Proposta commerciale di budget
A15: Volumi e prezzi proposti dalla direzione commerciale; costi variabili, tempi di ciclo e struttura base invariati; capitolo 12
A16: Voce | B16: Valore | C16: Unità | D16: Valore atteso (libro) | E16: Controllo | F16: Fonte nel libro
A17: Linea A - unità di budget | B17: =Impresa_guida!$B$8 -> 8000 | C17: unità | D17: 8000 | E17: =IF(ABS(B17-D17)<=0.5,"OK","DIVERSO") -> OK | F17: capitolo 12
A18: Linea A - prezzo di budget | B18: =Impresa_guida!$B$9 -> 180 | C18: euro/unità | D18: 180 | E18: =IF(ABS(B18-D18)<=0.5,"OK","DIVERSO") -> OK | F18: capitolo 12
A19: Linea B - unità di budget | B19: 11400 | C19: unità | F19: capitolo 12
A20: Linea B - prezzo di budget | B20: 118 | C20: euro/unità | F20: capitolo 12
A21: Linea C - unità di budget (obiettivo da verificare) | B21: 2100 | C21: unità | F21: capitolo 12
A22: Linea C - prezzo di budget | B22: =Impresa_guida!$B$17 -> 289 | C22: euro/unità | D22: 289 | E22: =IF(ABS(B22-D22)<=0.5,"OK","DIVERSO") -> OK | F22: capitolo 12
A24: Budget a margine dell'esercizio
A25: Ricavi, margine, ore, capacità esterna e risultato del budget; capitolo 12, capitolo 13
A26: Voce | B26: Valore | C26: Unità | D26: Valore atteso (libro) | E26: Controllo | F26: Fonte nel libro
A27: Unità vendute di budget | B27: =$B$17+$B$19+$B$21 -> 21500 | C27: unità | D27: 21500 | E27: =IF(ABS(B27-D27)<=0.5,"OK","DIVERSO") -> OK | F27: capitolo 13
A28: Ricavi di budget | B28: =$B$17*$B$18+$B$19*$B$20+$B$21*$B$22 -> 3392100 | C28: euro | D28: 3392100 | E28: =IF(ABS(B28-D28)<=0.5,"OK","DIVERSO") -> OK | F28: capitolo 13
A29: Costi variabili di budget | B29: =$B$17*Impresa_guida!$B$10+$B$19*Impresa_guida!$B$14+$B$21*Impresa_guida!$B$18 -> 2302200 | C29: euro | F29: capitolo 12
A30: Margine di contribuzione di budget | B30: =$B$28-$B$29 -> 1089900 | C30: euro | D30: 1089900 | E30: =IF(ABS(B30-D30)<=0.5,"OK","DIVERSO") -> OK | F30: capitolo 12
A31: Ore macchina di budget | B31: =$B$17*Impresa_guida!$B$11+$B$19*Impresa_guida!$B$15+$B$21*Impresa_guida!$B$19 -> 24000 | C31: ore | D31: 24000 | E31: =IF(ABS(B31-D31)<=0.5,"OK","DIVERSO") -> OK | F31: capitolo 12, capitolo 13
A32: Ore di capacità esterna | B32: =MAX($B$31-Impresa_guida!$B$26,0) -> 3000 | C32: ore | D32: 3000 | E32: =IF(ABS(B32-D32)<=0.5,"OK","DIVERSO") -> OK | F32: capitolo 12
A33: Costo della capacità esterna | B33: =$B$32*Impresa_guida!$B$27 -> 84000 | C33: euro | D33: 84000 | E33: =IF(ABS(B33-D33)<=0.5,"OK","DIVERSO") -> OK | F33: capitolo 12
A34: Costi della struttura di budget | B34: =Impresa_guida!$B$40+$B$33 -> 820000 | C34: euro | D34: 820000 | E34: =IF(ABS(B34-D34)<=0.5,"OK","DIVERSO") -> OK | F34: capitolo 12
A35: Risultato operativo di budget | B35: =$B$30-$B$34 -> 269900 | C35: euro | D35: 269900 | E35: =IF(ABS(B35-D35)<=0.5,"OK","DIVERSO") -> OK | F35: capitolo 12
A36: Miglioramento rispetto all'esercizio corrente | B36: =$B$35-$B$9 -> 27900 | C36: euro | D36: 27900 | E36: =IF(ABS(B36-D36)<=0.5,"OK","DIVERSO") -> OK | F36: capitolo 12
A38: Run rate, driver e iniziative
A39: Scomposizione del miglioramento in run rate, driver di volume e iniziativa di prezzo; capitolo 12, tabella
A40: Voce | B40: Valore | C40: Unità | D40: Valore atteso (libro) | E40: Controllo | F40: Fonte nel libro
A41: Driver: volume linea B | B41: =($B$19-Impresa_guida!$B$12)*$B$11 -> -22800 | C41: euro | D41: -22800 | E41: =IF(ABS(B41-D41)<=0.5,"OK","DIVERSO") -> OK | F41: capitolo 12
A42: Driver: volume linea C | B42: =($B$21-Impresa_guida!$B$16)*$B$12 -> 5100 | C42: euro | D42: 5100 | E42: =IF(ABS(B42-D42)<=0.5,"OK","DIVERSO") -> OK | F42: capitolo 12
A43: Iniziativa: recupero di prezzo linea B | B43: =($B$20-Impresa_guida!$B$13)*$B$19 -> 45600 | C43: euro | D43: 45600 | E43: =IF(ABS(B43-D43)<=0.5,"OK","DIVERSO") -> OK | F43: capitolo 12
